<?xml version="1.0"?>
<robot name="my_robot" xmlns:xacro="http://www.ros.org/wiki/xacro">

  <!-- Base link -->
  <link name="base_link">
    <inertial>
      <mass value="5.0"/>
      <origin xyz="0 0 0"/>
      <inertia ixx="1" ixy="0" ixz="0" iyy="1" iyz="0" izz="1"/>
    </inertial>
  </link>

  <!-- IMU -->
  <link name="imu_link"/>

  <joint name="imu_joint" type="fixed">
    <parent link="base_link"/>
    <child link="imu_link"/>
  </joint>

  <gazebo>
    <sensor name="imu_sensor" type="imu">
      <pose>0 0 0.2 0 0 0</pose>
      <topic>imu/data</topic>
    </sensor>
  </gazebo>

  <!-- Camera -->
  <link name="camera_link"/>
  <joint name="camera_joint" type="fixed">
    <parent link="base_link"/>
    <child link="camera_link"/>
  </joint>

  <gazebo reference="camera_link">
    <sensor name="camera" type="camera">
      <update_rate>30</update_rate>
      <topic>camera/image</topic>
      <camera>
        <horizontal_fov>1.05</horizontal_fov>
        <image>
          <width>640</width>
          <height>480</height>
        </image>
      </camera>
    </sensor>
  </gazebo>

  <!-- Wheels & Encoders -->
  <link name="left_wheel"/>
  <link name="right_wheel"/>

  <joint name="left_wheel_joint" type="continuous">
    <parent link="base_link"/>
    <child link="left_wheel"/>
    <axis xyz="0 1 0"/>
  </joint>

  <joint name="right_wheel_joint" type="continuous">
    <parent link="base_link"/>
    <child link="right_wheel"/>
    <axis xyz="0 1 0"/>
  </joint>

  <gazebo>
    <plugin
      filename="libignition-gazebo6-diff-drive-system.so"
      name="ignition::gazebo::systems::DiffDrive">
      <left_joint>left_wheel_joint</left_joint>
      <right_joint>right_wheel_joint</right_joint>
      <wheel_separation>0.4</wheel_separation>
      <wheel_radius>0.05</wheel_radius>
      <odom_topic>odom</odom_topic>
    </plugin>
  </gazebo>

</robot>
